<?xml version="1.0" encoding="UTF-8"?>
<!-- Generated by org.testng.reporters.JUnitReportReporter -->
<testsuite hostname="RACD-002157" name="TestClass.FlightTicketsSearch" tests="3" failures="0" timestamp="7 Jun 2019 06:40:56 GMT" time="83.104" errors="2">
  <testcase name="SearchTickets" time="32.558" classname="TestClass.FlightTicketsSearch"/>
  <testcase name="SearchTickets" time="11.210" classname="TestClass.FlightTicketsSearch">
    <error type="java.lang.AssertionError" message="Test case has been failed">
      <![CDATA[java.lang.AssertionError: Test case has been failed
	at org.testng.Assert.fail(Assert.java:94)
	at TestClass.FlightTicketsSearch.SearchTickets(FlightTicketsSearch.java:36)
	at sun.reflect.NativeMethodAccessorImpl.invoke0(Native Method)
	at sun.reflect.NativeMethodAccessorImpl.invoke(NativeMethodAccessorImpl.java:62)
	at sun.reflect.DelegatingMethodAccessorImpl.invoke(DelegatingMethodAccessorImpl.java:43)
	at java.lang.reflect.Method.invoke(Method.java:498)
	at org.testng.internal.MethodInvocationHelper.invokeMethod(MethodInvocationHelper.java:80)
	at org.testng.internal.Invoker.invokeMethod(Invoker.java:714)
	at org.testng.internal.Invoker.invokeTestMethod(Invoker.java:901)
	at org.testng.internal.Invoker.invokeTestMethods(Invoker.java:1231)
	at org.testng.internal.TestMethodWorker.invokeTestMethods(TestMethodWorker.java:127)
	at org.testng.internal.TestMethodWorker.run(TestMethodWorker.java:111)
	at org.testng.TestRunner.privateRun(TestRunner.java:767)
	at org.testng.TestRunner.run(TestRunner.java:617)
	at org.testng.SuiteRunner.runTest(SuiteRunner.java:334)
	at org.testng.SuiteRunner.access$000(SuiteRunner.java:37)
	at org.testng.SuiteRunner$SuiteWorker.run(SuiteRunner.java:368)
	at org.testng.internal.thread.ThreadUtil$2.call(ThreadUtil.java:64)
	at java.util.concurrent.FutureTask.run(FutureTask.java:266)
	at java.util.concurrent.ThreadPoolExecutor.runWorker(ThreadPoolExecutor.java:1149)
	at java.util.concurrent.ThreadPoolExecutor$Worker.run(ThreadPoolExecutor.java:624)
	at java.lang.Thread.run(Thread.java:748)
]]>
    </error>
  </testcase> <!-- SearchTickets -->
  <testcase name="SearchTickets" time="39.336" classname="TestClass.FlightTicketsSearch">
    <error type="java.lang.AssertionError" message="Test case has been failed">
      <![CDATA[java.lang.AssertionError: Test case has been failed
	at org.testng.Assert.fail(Assert.java:94)
	at TestClass.FlightTicketsSearch.SearchTickets(FlightTicketsSearch.java:36)
	at sun.reflect.NativeMethodAccessorImpl.invoke0(Native Method)
	at sun.reflect.NativeMethodAccessorImpl.invoke(NativeMethodAccessorImpl.java:62)
	at sun.reflect.DelegatingMethodAccessorImpl.invoke(DelegatingMethodAccessorImpl.java:43)
	at java.lang.reflect.Method.invoke(Method.java:498)
	at org.testng.internal.MethodInvocationHelper.invokeMethod(MethodInvocationHelper.java:80)
	at org.testng.internal.Invoker.invokeMethod(Invoker.java:714)
	at org.testng.internal.Invoker.invokeTestMethod(Invoker.java:901)
	at org.testng.internal.Invoker.invokeTestMethods(Invoker.java:1231)
	at org.testng.internal.TestMethodWorker.invokeTestMethods(TestMethodWorker.java:127)
	at org.testng.internal.TestMethodWorker.run(TestMethodWorker.java:111)
	at org.testng.TestRunner.privateRun(TestRunner.java:767)
	at org.testng.TestRunner.run(TestRunner.java:617)
	at org.testng.SuiteRunner.runTest(SuiteRunner.java:334)
	at org.testng.SuiteRunner.access$000(SuiteRunner.java:37)
	at org.testng.SuiteRunner$SuiteWorker.run(SuiteRunner.java:368)
	at org.testng.internal.thread.ThreadUtil$2.call(ThreadUtil.java:64)
	at java.util.concurrent.FutureTask.run(FutureTask.java:266)
	at java.util.concurrent.ThreadPoolExecutor.runWorker(ThreadPoolExecutor.java:1149)
	at java.util.concurrent.ThreadPoolExecutor$Worker.run(ThreadPoolExecutor.java:624)
	at java.lang.Thread.run(Thread.java:748)
]]>
    </error>
  </testcase> <!-- SearchTickets -->
</testsuite> <!-- TestClass.FlightTicketsSearch -->
